Workbook

Sheet Constants
A1: TUNING CONSTANTS
A3: Mitigation
A4: K_DEF | B4: 100 | C4: Physical mitigation soft-cap. Mitigation% = DEF/(DEF+K_DEF).
A5: K_elem | B5: 80 | C5: Elemental mitigation soft-cap (shared across elements).
A7: Damage Variance
A8: VarianceMin | B8: 0.85
A9: VarianceMax | B9: 1.15
A11: Critical Hits
A12: BaseCritChance | B12: 0.05
A13: MaxCritChanceBonus | B13: 0.65
A14: K_crit | B14: 300
A15: BaseCritMult | B15: 1.5
A16: MaxCritMultBonus | B16: 2.5
A17: K_critmult | B17: 300
A19: Elemental Type Multipliers
A20: Weak | B20: 1.5
A21: Neutral | B21: 1
A22: Resistant | B22: 0.5
A23: Immune | B23: 0
A25: Reincarnation / Difficulty
A26: r (player power bonus/loop) | B26: 0.1
A27: d (enemy difficulty growth/loop) | B27: 0.15
A29: Stat Scaling
A30: STR_Divisor | B30: 100
A31: INT_Divisor | B31: 100
A33: Health
A34: BaseHP | B34: 100
A35: HPperVIT | B35: 10
A37: Weapon Archetypes — Base Cooldown (sec)
A38: Weapon | B38: Base Cooldown
A39: Dagger | B39: 0.8
A40: Wand | B40: 0.9
A41: Sword | B41: 1
A42: Bow | B42: 1
A43: Axe | B43: 1.1
A44: Mace | B44: 1.1
A45: Staff | B45: 1.2
A46: Tome | B46: 1.3
A47: Greatsword | B47: 1.8
A49: Haste & Cooldown Reduction
...

Sheet GearTiers
A1: GEAR TIERS & EQUIPMENT STAT BUDGETS
A2: Standardized equipment budgets across 11 loadout slots per zone/character progression tier.
A3: Tier Name | B3: Rec Level | C3: WeaponBase | D3: SkillBase | E3: STR Bonus | F3: INT Bonus | G3: VIT Bonus | H3: DEF Bonus | I3: AGI Bonus | J3: LUK Bonus | K3: Armor DEF | L3: Shield Block % | M3: Description / Rarity
A4: Tier 0 (Starter) | B4: 1 | C4: 20 | D4: 20 | E4: 0 | F4: 0 | G4: 0 | H4: 0 | I4: 0 | J4: 0 | K4: 0 | L4: 0.1 | M4: Common / Tattered Starter Gear & Rusty Sword
A5: Tier 1 (Common) | B5: 5 | C5: 35 | D5: 35 | E5: 10 | F5: 10 | G5: 10 | H5: 15 | I5: 5 | J5: 5 | K5: 15 | L5: 0.15 | M5: Apprentice Iron / Boiled Leather (Zone Tier 1)
A6: Tier 2 (Uncommon) | B6: 25 | C6: 65 | D6: 65 | E6: 25 | F6: 25 | G6: 25 | H6: 35 | I6: 15 | J6: 15 | K6: 35 | L6: 0.2 | M6: Tempered Steel / Hardened Chainmail (Zone Tier 2)
A7: Tier 3 (Rare) | B7: 50 | C7: 120 | D7: 120 | E7: 60 | F7: 60 | G7: 60 | H7: 80 | I7: 35 | J7: 35 | K7: 80 | L7: 0.25 | M7: Mastercrafted Mithril / Enchanted Plate (Zone Tier 3)
A8: Tier 4 (Epic) | B8: 100 | C8: 240 | D8: 240 | E8: 130 | F8: 130 | G8: 130 | H8: 180 | I8: 75 | J8: 75 | K8: 180 | L8: 0.3 | M8: Dragonforged Relics / Void-Infused Armor (Zone Tier 4)
A9: Tier 5 (Legendary) | B9: 200 | C9: 400 | D9: 400 | E9: 250 | F9: 250 | G9: 250 | H9: 350 | I9: 150 | J9: 150 | K9: 350 | L9: 0.35 | M9: Prestige Artifacts / Max Rebirth Cap (Zone Tier 5)

Sheet PlayerBuild
A1: PLAYER BUILD
A3: Level | B3: 1 | C3: Stat Points Earned: | D3: =MAX(0, (B3-1)*Constants!$B$90)
A4: Reincarnations (N) | B4: 0 | C4: Unspent Points: | D4: =D3-SUM(C11:C16)
A5: Class | B5: Melee DPS
A6: Main-Hand Weapon | B6: Sword
A7: Off-Hand | B7: Dual-Wield Weapon
A8: Equipped Gear Tier | B8: Tier 0 (Starter)
A9: Core Stats
A10: Stat | B10: Base | C10: Allocated Points | D10: Gear Bonus | E10: Total | F10: Alloc %
A11: STR | B11: 5 | C11: =ROUND($D$3*F11, 0) | D11: =IF($B$8="Custom", 0, VLOOKUP($B$8, GearTiers!$A$4:$J$9, 5, FALSE)) | E11: =SUM(B11:D11) | F11: 0.5
A12: INT | B12: 5 | C12: =ROUND($D$3*F12, 0) | D12: =IF($B$8="Custom", 0, VLOOKUP($B$8, GearTiers!$A$4:$J$9, 6, FALSE)) | E12: =SUM(B12:D12) | F12: 0
A13: VIT | B13: 10 | C13: =ROUND($D$3*F13, 0) | D13: =IF($B$8="Custom", 0, VLOOKUP($B$8, GearTiers!$A$4:$J$9, 7, FALSE)) | E13: =SUM(B13:D13) | F13: 0.2
A14: DEF | B14: 5 | C14: =ROUND($D$3*F14, 0) | D14: =IF($B$8="Custom", 0, VLOOKUP($B$8, GearTiers!$A$4:$J$9, 8, FALSE)) | E14: =SUM(B14:D14) | F14: 0.1
A15: AGI | B15: 5 | C15: =ROUND($D$3*F15, 0) | D15: =IF($B$8="Custom", 0, VLOOKUP($B$8, GearTiers!$A$4:$J$9, 9, FALSE)) | E15: =SUM(B15:D15) | F15: 0.1
A16: LUK | B16: 5 | C16: =ROUND($D$3*F16, 0) | D16: =IF($B$8="Custom", 0, VLOOKUP($B$8, GearTiers!$A$4:$J$9, 10, FALSE)) | E16: =SUM(B16:D16) | F16: 0.1
A18: Elemental Resistances
A19: Element | B19: Base | C19: Allocated Points | D19: Gear Bonus | E19: Total
A20: Fire | B20: 0 | C20: 0 | D20: 0 | E20: =SUM(B20:D20)
A21: Ice | B21: 0 | C21: 0 | D21: 0 | E21: =SUM(B21:D21)
A22: Lightning | B22: 0 | C22: 0 | D22: 0 | E22: =SUM(B22:D22)
A23: Poison | B23: 0 | C23: 0 | D23: 0 | E23: =SUM(B23:D23)
A25: Loadout & Derived
A26: Weapon Base Damage (physical) | B26: =IF($B$8="Custom", 20, VLOOKUP($B$8, GearTiers!$A$4:$J$9, 3, FALSE))
A27: Skill Base Damage (elemental) | B27: =IF($B$8="Custom", 20, VLOOKUP($B$8, GearTiers!$A$4:$J$9, 4, FALSE))
A28: Max HP | B28: =Constants!B34+E13*Constants!B35
A29: Prestige Multiplier | B29: =(1+Constants!B26)^B4
A31: Weapon Speed & Mastery (derived)
A32: Base Weapon Cooldown (sec) | B32: =INDEX(Constants!B39:B47,MATCH(B6,Constants!A39:A47,0))
A33: Haste % (from AGI) | B33: =E15/(E15+Constants!B50)
A34: Dual-Wield CDR Bonus | B34: =IF(B7="Dual-Wield Weapon",Constants!B54+IF(B5="Melee DPS",Constants!B57,0),0)
A35: Total Cooldown Reduction % | B35: =MIN(B33+B34,Constants!B51)
A36: Effective Basic Attack Cooldown (sec) | B36: =B32*(1-B35)
A37: Attacks Per Second | B37: =1/B36
A39: Block Chance % (if Shield equipped) | B39: =IF(B7="Shield",Constants!B68+IF(B5="Tank",Constants!B58,0),0)
A40: Shield & Armor DEF Bonus (flat) | B40: =IF(B7="Shield",Constants!B69+IF(B5="Tank",Constants!B59,0),0) + IF($B$8="Custom",0,VLOOKUP($B$8,GearTiers!$A$4:$K$9,11,FALSE))
A41: Ranged Bonus Crit Chance % (Bow) | B41: =IF(AND(B5="Ranged DPS",B6="Bow"),Constants!B60,0)
A42: Ranged Bonus Damage % (Bow) | B42: =IF(AND(B5="Ranged DPS",B6="Bow"),Constants!B61,0)
A43: Caster Bonus Damage % (Staff) | B43: =IF(AND(B5="Caster DPS",B6="Staff"),Constants!B62,0)
A44: Caster Bonus Crit % (Staff) | B44: =IF(AND(B5="Caster DPS",B6="Staff"),Constants!B63,0)
A45: Caster Bonus Penetration % (Staff) | B45: =IF(AND(B5="Caster DPS",B6="Staff"),Constants!B64,0)
...

Sheet EnemyBuild
A1: ENEMY BUILD
A2: Full stat parity with PlayerBuild — enemies use the exact same abilities, so they need the exact same stat block and mastery system.
A4: Zone Tier / Loop (N) | B4: 0
A5: Class | B5: Melee DPS
A6: Main-Hand Weapon | B6: Sword
A7: Off-Hand | B7: None
A8: Attack Element (primary, vs player) | B8: Physical
A9: Weakness Category (encounter design, vs player's element) | B9: Neutral
A11: Difficulty Multiplier | B11: =(1+Constants!B27)^B4 | C11: Enemy's equivalent of the player's Prestige Multiplier.
A13: Core Stats
A14: Stat | B14: Base | C14: Scaled Total
A15: STR | B15: 15 | C15: =B15*$B$11
A16: INT | B16: 5 | C16: =B16*$B$11
A17: VIT | B17: 10 | C17: =B17*$B$11
A18: DEF | B18: 15 | C18: =B18*$B$11
A19: AGI | B19: 5 | C19: =B19*$B$11
A20: LUK | B20: 5 | C20: =B20*$B$11
A22: Elemental Resistances
A23: Element | B23: Base | C23: Scaled Total
A24: Fire | B24: 0 | C24: =B24*$B$11
A25: Ice | B25: 0 | C25: =B25*$B$11
A26: Lightning | B26: 0 | C26: =B26*$B$11
A27: Poison | B27: 0 | C27: =B27*$B$11
A29: Loadout & Derived
A30: Weapon Base Damage (physical) | B30: 15
A31: Skill Base Damage (elemental) | B31: 15
A32: Max HP | B32: =Constants!B34+C17*Constants!B35
A34: Weapon Speed & Mastery (derived)
A35: Base Weapon Cooldown (sec) | B35: =INDEX(Constants!B39:B47,MATCH(B6,Constants!A39:A47,0))
A36: Haste % (from AGI) | B36: =C19/(C19+Constants!B50)
A37: Dual-Wield CDR Bonus | B37: =IF(B7="Dual-Wield Weapon",Constants!B54+IF(B5="Melee DPS",Constants!B57,0),0)
A38: Total Cooldown Reduction % | B38: =MIN(B36+B37,Constants!B51)
A39: Effective Basic Attack Cooldown (sec) | B39: =B35*(1-B38)
A40: Attacks Per Second | B40: =1/B39
A42: Block Chance % (if Shield equipped) | B42: =IF(B7="Shield",Constants!B68+IF(B5="Tank",Constants!B58,0),0)
A43: Shield DEF Bonus (flat) | B43: =IF(B7="Shield",Constants!B69+IF(B5="Tank",Constants!B59,0),0)
A44: Ranged Bonus Crit Chance % (Bow) | B44: =IF(AND(B5="Ranged DPS",B6="Bow"),Constants!B60,0)
A45: Ranged Bonus Damage % (Bow) | B45: =IF(AND(B5="Ranged DPS",B6="Bow"),Constants!B61,0)
A46: Caster Bonus Damage % (Staff) | B46: =IF(AND(B5="Caster DPS",B6="Staff"),Constants!B62,0)
A47: Caster Bonus Crit % (Staff) | B47: =IF(AND(B5="Caster DPS",B6="Staff"),Constants!B63,0)
...

Sheet Calculator
A1: DAMAGE & TTK CALCULATOR
A3: Physical Attack — Player vs Enemy
A4: Raw Damage | B4: =PlayerBuild!B26*(1+PlayerBuild!E11/Constants!B30)
A5: Mitigation % | B5: =EnemyBuild!C18/(EnemyBuild!C18+Constants!B4)
A6: Mitigated Damage | B6: =B4*(1-B5)
A7: Type Multiplier | B7: =IF(EnemyBuild!B9="Weak",Constants!B20,IF(EnemyBuild!B9="Resistant",Constants!B22,IF(EnemyBuild!B9="Immune",Constants!B23,Constants!B21)))
A8: Typed Damage | B8: =B6*B7
A9: Crit Chance % | B9: =Constants!B12+(PlayerBuild!E16/(PlayerBuild!E16+Constants!B14))*Constants!B13+PlayerBuild!B41
A10: Crit Multiplier | B10: =Constants!B15+(PlayerBuild!E16/(PlayerBuild!E16+Constants!B17))*Constants!B16
A11: Average Damage (crit-weighted) | B11: =B8*(1+B9*(B10-1))
A12: Ranged Damage Bonus Multiplier | B12: =1+PlayerBuild!B42
A13: Prestige Multiplier | B13: =PlayerBuild!B29
A14: Final Average Damage / Hit | B14: =B11*B12*B13
A15: Attacks Per Second | B15: =PlayerBuild!B37
A16: DPS (Physical) | B16: =B14*B15
A17: Enemy HP (scaled) | B17: =EnemyBuild!B32
A18: Time to Kill (sec) | B18: =B17/B16
A19: Hits to Kill (reference) | B19: =ROUNDUP(B17/B14,0)
A20: Target Check | B20: =IF(AND(B19>=4,B19<=8),"In target range (4-8 hits)","Outside target range (4-8 hits)")
A22: Elemental Attack — Player vs Enemy
A23: Raw Damage | B23: =PlayerBuild!B27*(1+PlayerBuild!E12/Constants!B31)
A24: Enemy RES (matching Skill Element) | B24: =IF(PlayerBuild!B50="Fire",EnemyBuild!C24,IF(PlayerBuild!B50="Ice",EnemyBuild!C25,IF(PlayerBuild!B50="Lightning",EnemyBuild!C26,EnemyBuild!C27)))
A25: Elemental Penetration % | B25: =PlayerBuild!B45
A26: Effective Enemy RES (after Penetration) | B26: =B24*(1-B25)
A27: Mitigation % | B27: =B26/(B26+Constants!B5)
A28: Mitigated Damage | B28: =B23*(1-B27)
A29: Type Multiplier | B29: =B7
A30: Typed Damage | B30: =B28*B29
A31: Elemental Crit Chance % | B31: =Constants!B12+(PlayerBuild!E16/(PlayerBuild!E16+Constants!B14))*Constants!B13+PlayerBuild!B44
A32: Elemental Crit Multiplier | B32: =Constants!B15+(PlayerBuild!E16/(PlayerBuild!E16+Constants!B17))*Constants!B16
A33: Average Damage (crit-weighted) | B33: =B30*(1+B31*(B32-1))
A34: Caster Damage Bonus Multiplier | B34: =1+PlayerBuild!B43
A35: Prestige Multiplier | B35: =B13
A36: Final Average Damage / Hit | B36: =B33*B34*B35
A37: Attacks Per Second | B37: =PlayerBuild!B37
A38: DPS (Elemental) | B38: =B36*B37
A39: Enemy HP (scaled) | B39: =B17
A40: Time to Kill (sec) | B40: =B39/B38
A41: Hits to Kill (reference) | B41: =ROUNDUP(B39/B36,0)
A42: Target Check | B42: =IF(AND(B41>=4,B41<=8),"In target range (4-8 hits)","Outside target range (4-8 hits)")
...

Sheet Leveling
A1: EXPERIENCE & LEVELING
A2: XPRequired(Level,Loop) = XPBase × (1+XPGrowth)^(Level-1) × (1+d)^Loop. Reuses Constants!d and Constants!r so leveling scales with combat difficulty/prestige.
A4: Sample XP-Per-Level
A5: Loop N (for this table) | B5: 0
A7: Level | B7: XP Required (this level)
A8: 1 | B8: =Constants!$B$73*(1+Constants!$B$74)^(A8-1)*(1+Constants!$B$27)^$B$5
A9: 10 | B9: =Constants!$B$73*(1+Constants!$B$74)^(A9-1)*(1+Constants!$B$27)^$B$5
A10: 25 | B10: =Constants!$B$73*(1+Constants!$B$74)^(A10-1)*(1+Constants!$B$27)^$B$5
A11: 50 | B11: =Constants!$B$73*(1+Constants!$B$74)^(A11-1)*(1+Constants!$B$27)^$B$5
A12: 75 | B12: =Constants!$B$73*(1+Constants!$B$74)^(A12-1)*(1+Constants!$B$27)^$B$5
A13: 100 | B13: =Constants!$B$73*(1+Constants!$B$74)^(A13-1)*(1+Constants!$B$27)^$B$5
A14: 150 | B14: =Constants!$B$73*(1+Constants!$B$74)^(A14-1)*(1+Constants!$B$27)^$B$5
A15: 200 | B15: =Constants!$B$73*(1+Constants!$B$74)^(A15-1)*(1+Constants!$B$27)^$B$5
A16: 250 | B16: =Constants!$B$73*(1+Constants!$B$74)^(A16-1)*(1+Constants!$B$27)^$B$5
A17: 300 | B17: =Constants!$B$73*(1+Constants!$B$74)^(A17-1)*(1+Constants!$B$27)^$B$5
A19: Total XP to Level Cap (per Loop)
A20: Loop N | B20: Total XP to Cap
A21: 0 | B21: =Constants!$B$73*(1+Constants!$B$27)^A21*((1+Constants!$B$74)^Constants!$B$75-1)/Constants!$B$74
A22: 1 | B22: =Constants!$B$73*(1+Constants!$B$27)^A22*((1+Constants!$B$74)^Constants!$B$75-1)/Constants!$B$74
A23: 2 | B23: =Constants!$B$73*(1+Constants!$B$27)^A23*((1+Constants!$B$74)^Constants!$B$75-1)/Constants!$B$74
A24: 3 | B24: =Constants!$B$73*(1+Constants!$B$27)^A24*((1+Constants!$B$74)^Constants!$B$75-1)/Constants!$B$74
A25: 4 | B25: =Constants!$B$73*(1+Constants!$B$27)^A25*((1+Constants!$B$74)^Constants!$B$75-1)/Constants!$B$74
A26: 5 | B26: =Constants!$B$73*(1+Constants!$B$27)^A26*((1+Constants!$B$74)^Constants!$B$75-1)/Constants!$B$74
A28: Pacing Calculator (Loop 0)
A29: Daily Kill Capacity | B29: =Constants!B83*Constants!B85+Constants!B84*Constants!B86
A30: Total Kills to Cap (approx) | B30: =Constants!B75*Constants!B76
A31: Implied Days to Cap (Loop 0) | B31: =B30/B29
A32: Target Days to Rebirth | B32: =Constants!B87
A33: Target Check | B33: =IF(ABS(B31-B32)<=B32*0.15,"Within 15% of target — good calibration","Adjust KillsPerLevel or kill-rate assumptions")
A35: Rebirth Pacing Projection
A36: Loop N | B36: Difficulty Mult (1+d)^N | C36: Prestige Mult (1+r)^N | D36: Relative Slowdown | E36: Implied Days (this loop)
A37: 0 | B37: =(1+Constants!$B$27)^A37 | C37: =(1+Constants!$B$26)^A37 | D37: =((1+Constants!$B$27)/(1+Constants!$B$26))^A37 | E37: =$B$31*D37
A38: 1 | B38: =(1+Constants!$B$27)^A38 | C38: =(1+Constants!$B$26)^A38 | D38: =((1+Constants!$B$27)/(1+Constants!$B$26))^A38 | E38: =$B$31*D38
A39: 2 | B39: =(1+Constants!$B$27)^A39 | C39: =(1+Constants!$B$26)^A39 | D39: =((1+Constants!$B$27)/(1+Constants!$B$26))^A39 | E39: =$B$31*D39
A40: 3 | B40: =(1+Constants!$B$27)^A40 | C40: =(1+Constants!$B$26)^A40 | D40: =((1+Constants!$B$27)/(1+Constants!$B$26))^A40 | E40: =$B$31*D40
A41: 4 | B41: =(1+Constants!$B$27)^A41 | C41: =(1+Constants!$B$26)^A41 | D41: =((1+Constants!$B$27)/(1+Constants!$B$26))^A41 | E41: =$B$31*D41
A42: 5 | B42: =(1+Constants!$B$27)^A42 | C42: =(1+Constants!$B$26)^A42 | D42: =((1+Constants!$B$27)/(1+Constants!$B$26))^A42 | E42: =$B$31*D42
A44: Cumulative Days (Loop 0 through selected loop) | B44: =SUM(E37:E42) | C44: Sum of all 6 sample loops shown above — a rough total-playtime-to-loop-5 estimate.
A46: Enemy XP Calculator
A47: Player Level | B47: 50
...

Sheet ProgressionCurve
A1: PROGRESSION DYNAMICS: LEVELING VS. GEAR (LEVEL 1 TO 200)
A2: Benchmark comparison isolating the impact of level-up stat point allocation vs. on-tier gear acquisition.
A4: CHARACTER STATE | D4: LEVELING ONLY (Starter Weapon 20, 0 Gear) | I4: GEAR ONLY (Base Stats 10, On-Tier Gear) | N4: COMBINED (Leveling + On-Tier Gear) | T4: BALANCE & POWER SHARE
A5: Level | B5: Stat Points | C5: Gear Tier | D5: STR | E5: Max HP | F5: Hit Dmg | G5: DPS | H5: Power Mult | I5: WeaponBase | J5: STR | K5: Max HP | L5: DPS | M5: Power Mult | N5: Total STR | O5: Max HP | P5: Armor DEF | Q5: Hit Dmg | R5: DPS | S5: Power Mult | T5: Level Share % | U5: Gear Share % | V5: TTK vs Grunt | W5: Target Hits
A6: 1 | B6: =(A6-1)*Constants!$B$90 | C6: Tier 0 (Starter) | D6: =10+ROUND(B6*0.5, 0) | E6: =100+(10+ROUND(B6*0.2, 0))*Constants!$B$35 | F6: =20*(1+D6/Constants!$B$30)*(Constants!$B$4/(Constants!$B$4+10)) | G6: =F6/(1-(10+ROUND(B6*0.1, 0))/(10+ROUND(B6*0.1, 0)+Constants!$B$50)) | H6: =G6/$G$6 | I6: =VLOOKUP(C6, GearTiers!$A$4:$J$9, 3, FALSE) | J6: =10+VLOOKUP(C6, GearTiers!$A$4:$J$9, 5, FALSE) | K6: =100+(10+VLOOKUP(C6, GearTiers!$A$4:$J$9, 7, FALSE))*Constants!$B$35 | L6: =(I6*(1+J6/Constants!$B$30)*(Constants!$B$4/(Constants!$B$4+10)))/(1-(10+VLOOKUP(C6, GearTiers!$A$4:$J$9, 9, FALSE))/(10+VLOOKUP(C6, GearTiers!$A$4:$J$9, 9, FALSE)+Constants!$B$50)) | M6: =L6/$L$6 | N6: =D6+VLOOKUP(C6, GearTiers!$A$4:$J$9, 5, FALSE) | O6: =E6+VLOOKUP(C6, GearTiers!$A$4:$J$9, 7, FALSE)*Constants!$B$35 | P6: =10+ROUND(B6*0.1, 0)+VLOOKUP(C6, GearTiers!$A$4:$K$9, 8, FALSE) | Q6: =I6*(1+N6/Constants!$B$30)*(Constants!$B$4/(Constants!$B$4+10)) | R6: =Q6/(1-(10+ROUND(B6*0.1, 0)+VLOOKUP(C6, GearTiers!$A$4:$J$9, 9, FALSE))/(10+ROUND(B6*0.1, 0)+VLOOKUP(C6, GearTiers!$A$4:$J$9, 9, FALSE)+Constants!$B$50)) | S6: =R6/$R$6 | T6: =H6/(H6+M6) | U6: =M6/(H6+M6) | V6: =100/R6 | W6: =ROUNDUP(100/Q6, 0)
A7: 5 | B7: =(A7-1)*Constants!$B$90 | C7: Tier 1 (Common) | D7: =10+ROUND(B7*0.5, 0) | E7: =100+(10+ROUND(B7*0.2, 0))*Constants!$B$35 | F7: =20*(1+D7/Constants!$B$30)*(Constants!$B$4/(Constants!$B$4+10)) | G7: =F7/(1-(10+ROUND(B7*0.1, 0))/(10+ROUND(B7*0.1, 0)+Constants!$B$50)) | H7: =G7/$G$6 | I7: =VLOOKUP(C7, GearTiers!$A$4:$J$9, 3, FALSE) | J7: =10+VLOOKUP(C7, GearTiers!$A$4:$J$9, 5, FALSE) | K7: =100+(10+VLOOKUP(C7, GearTiers!$A$4:$J$9, 7, FALSE))*Constants!$B$35 | L7: =(I7*(1+J7/Constants!$B$30)*(Constants!$B$4/(Constants!$B$4+10)))/(1-(10+VLOOKUP(C7, GearTiers!$A$4:$J$9, 9, FALSE))/(10+VLOOKUP(C7, GearTiers!$A$4:$J$9, 9, FALSE)+Constants!$B$50)) | M7: =L7/$L$6 | N7: =D7+VLOOKUP(C7, GearTiers!$A$4:$J$9, 5, FALSE) | O7: =E7+VLOOKUP(C7, GearTiers!$A$4:$J$9, 7, FALSE)*Constants!$B$35 | P7: =10+ROUND(B7*0.1, 0)+VLOOKUP(C7, GearTiers!$A$4:$K$9, 8, FALSE) | Q7: =I7*(1+N7/Constants!$B$30)*(Constants!$B$4/(Constants!$B$4+10)) | R7: =Q7/(1-(10+ROUND(B7*0.1, 0)+VLOOKUP(C7, GearTiers!$A$4:$J$9, 9, FALSE))/(10+ROUND(B7*0.1, 0)+VLOOKUP(C7, GearTiers!$A$4:$J$9, 9, FALSE)+Constants!$B$50)) | S7: =R7/$R$6 | T7: =H7/(H7+M7) | U7: =M7/(H7+M7) | V7: =100/R7 | W7: =ROUNDUP(100/Q7, 0)
A8: 10 | B8: =(A8-1)*Constants!$B$90 | C8: Tier 1 (Common) | D8: =10+ROUND(B8*0.5, 0) | E8: =100+(10+ROUND(B8*0.2, 0))*Constants!$B$35 | F8: =20*(1+D8/Constants!$B$30)*(Constants!$B$4/(Constants!$B$4+10)) | G8: =F8/(1-(10+ROUND(B8*0.1, 0))/(10+ROUND(B8*0.1, 0)+Constants!$B$50)) | H8: =G8/$G$6 | I8: =VLOOKUP(C8, GearTiers!$A$4:$J$9, 3, FALSE) | J8: =10+VLOOKUP(C8, GearTiers!$A$4:$J$9, 5, FALSE) | K8: =100+(10+VLOOKUP(C8, GearTiers!$A$4:$J$9, 7, FALSE))*Constants!$B$35 | L8: =(I8*(1+J8/Constants!$B$30)*(Constants!$B$4/(Constants!$B$4+10)))/(1-(10+VLOOKUP(C8, GearTiers!$A$4:$J$9, 9, FALSE))/(10+VLOOKUP(C8, GearTiers!$A$4:$J$9, 9, FALSE)+Constants!$B$50)) | M8: =L8/$L$6 | N8: =D8+VLOOKUP(C8, GearTiers!$A$4:$J$9, 5, FALSE) | O8: =E8+VLOOKUP(C8, GearTiers!$A$4:$J$9, 7, FALSE)*Constants!$B$35 | P8: =10+ROUND(B8*0.1, 0)+VLOOKUP(C8, GearTiers!$A$4:$K$9, 8, FALSE) | Q8: =I8*(1+N8/Constants!$B$30)*(Constants!$B$4/(Constants!$B$4+10)) | R8: =Q8/(1-(10+ROUND(B8*0.1, 0)+VLOOKUP(C8, GearTiers!$A$4:$J$9, 9, FALSE))/(10+ROUND(B8*0.1, 0)+VLOOKUP(C8, GearTiers!$A$4:$J$9, 9, FALSE)+Constants!$B$50)) | S8: =R8/$R$6 | T8: =H8/(H8+M8) | U8: =M8/(H8+M8) | V8: =100/R8 | W8: =ROUNDUP(100/Q8, 0)
A9: 20 | B9: =(A9-1)*Constants!$B$90 | C9: Tier 2 (Uncommon) | D9: =10+ROUND(B9*0.5, 0) | E9: =100+(10+ROUND(B9*0.2, 0))*Constants!$B$35 | F9: =20*(1+D9/Constants!$B$30)*(Constants!$B$4/(Constants!$B$4+10)) | G9: =F9/(1-(10+ROUND(B9*0.1, 0))/(10+ROUND(B9*0.1, 0)+Constants!$B$50)) | H9: =G9/$G$6 | I9: =VLOOKUP(C9, GearTiers!$A$4:$J$9, 3, FALSE) | J9: =10+VLOOKUP(C9, GearTiers!$A$4:$J$9, 5, FALSE) | K9: =100+(10+VLOOKUP(C9, GearTiers!$A$4:$J$9, 7, FALSE))*Constants!$B$35 | L9: =(I9*(1+J9/Constants!$B$30)*(Constants!$B$4/(Constants!$B$4+10)))/(1-(10+VLOOKUP(C9, GearTiers!$A$4:$J$9, 9, FALSE))/(10+VLOOKUP(C9, GearTiers!$A$4:$J$9, 9, FALSE)+Constants!$B$50)) | M9: =L9/$L$6 | N9: =D9+VLOOKUP(C9, GearTiers!$A$4:$J$9, 5, FALSE) | O9: =E9+VLOOKUP(C9, GearTiers!$A$4:$J$9, 7, FALSE)*Constants!$B$35 | P9: =10+ROUND(B9*0.1, 0)+VLOOKUP(C9, GearTiers!$A$4:$K$9, 8, FALSE) | Q9: =I9*(1+N9/Constants!$B$30)*(Constants!$B$4/(Constants!$B$4+10)) | R9: =Q9/(1-(10+ROUND(B9*0.1, 0)+VLOOKUP(C9, GearTiers!$A$4:$J$9, 9, FALSE))/(10+ROUND(B9*0.1, 0)+VLOOKUP(C9, GearTiers!$A$4:$J$9, 9, FALSE)+Constants!$B$50)) | S9: =R9/$R$6 | T9: =H9/(H9+M9) | U9: =M9/(H9+M9) | V9: =100/R9 | W9: =ROUNDUP(100/Q9, 0)
A10: 35 | B10: =(A10-1)*Constants!$B$90 | C10: Tier 2 (Uncommon) | D10: =10+ROUND(B10*0.5, 0) | E10: =100+(10+ROUND(B10*0.2, 0))*Constants!$B$35 | F10: =20*(1+D10/Constants!$B$30)*(Constants!$B$4/(Constants!$B$4+10)) | G10: =F10/(1-(10+ROUND(B10*0.1, 0))/(10+ROUND(B10*0.1, 0)+Constants!$B$50)) | H10: =G10/$G$6 | I10: =VLOOKUP(C10, GearTiers!$A$4:$J$9, 3, FALSE) | J10: =10+VLOOKUP(C10, GearTiers!$A$4:$J$9, 5, FALSE) | K10: =100+(10+VLOOKUP(C10, GearTiers!$A$4:$J$9, 7, FALSE))*Constants!$B$35 | L10: =(I10*(1+J10/Constants!$B$30)*(Constants!$B$4/(Constants!$B$4+10)))/(1-(10+VLOOKUP(C10, GearTiers!$A$4:$J$9, 9, FALSE))/(10+VLOOKUP(C10, GearTiers!$A$4:$J$9, 9, FALSE)+Constants!$B$50)) | M10: =L10/$L$6 | N10: =D10+VLOOKUP(C10, GearTiers!$A$4:$J$9, 5, FALSE) | O10: =E10+VLOOKUP(C10, GearTiers!$A$4:$J$9, 7, FALSE)*Constants!$B$35 | P10: =10+ROUND(B10*0.1, 0)+VLOOKUP(C10, GearTiers!$A$4:$K$9, 8, FALSE) | Q10: =I10*(1+N10/Constants!$B$30)*(Constants!$B$4/(Constants!$B$4+10)) | R10: =Q10/(1-(10+ROUND(B10*0.1, 0)+VLOOKUP(C10, GearTiers!$A$4:$J$9, 9, FALSE))/(10+ROUND(B10*0.1, 0)+VLOOKUP(C10, GearTiers!$A$4:$J$9, 9, FALSE)+Constants!$B$50)) | S10: =R10/$R$6 | T10: =H10/(H10+M10) | U10: =M10/(H10+M10) | V10: =100/R10 | W10: =ROUNDUP(100/Q10, 0)
A11: 50 | B11: =(A11-1)*Constants!$B$90 | C11: Tier 3 (Rare) | D11: =10+ROUND(B11*0.5, 0) | E11: =100+(10+ROUND(B11*0.2, 0))*Constants!$B$35 | F11: =20*(1+D11/Constants!$B$30)*(Constants!$B$4/(Constants!$B$4+10)) | G11: =F11/(1-(10+ROUND(B11*0.1, 0))/(10+ROUND(B11*0.1, 0)+Constants!$B$50)) | H11: =G11/$G$6 | I11: =VLOOKUP(C11, GearTiers!$A$4:$J$9, 3, FALSE) | J11: =10+VLOOKUP(C11, GearTiers!$A$4:$J$9, 5, FALSE) | K11: =100+(10+VLOOKUP(C11, GearTiers!$A$4:$J$9, 7, FALSE))*Constants!$B$35 | L11: =(I11*(1+J11/Constants!$B$30)*(Constants!$B$4/(Constants!$B$4+10)))/(1-(10+VLOOKUP(C11, GearTiers!$A$4:$J$9, 9, FALSE))/(10+VLOOKUP(C11, GearTiers!$A$4:$J$9, 9, FALSE)+Constants!$B$50)) | M11: =L11/$L$6 | N11: =D11+VLOOKUP(C11, GearTiers!$A$4:$J$9, 5, FALSE) | O11: =E11+VLOOKUP(C11, GearTiers!$A$4:$J$9, 7, FALSE)*Constants!$B$35 | P11: =10+ROUND(B11*0.1, 0)+VLOOKUP(C11, GearTiers!$A$4:$K$9, 8, FALSE) | Q11: =I11*(1+N11/Constants!$B$30)*(Constants!$B$4/(Constants!$B$4+10)) | R11: =Q11/(1-(10+ROUND(B11*0.1, 0)+VLOOKUP(C11, GearTiers!$A$4:$J$9, 9, FALSE))/(10+ROUND(B11*0.1, 0)+VLOOKUP(C11, GearTiers!$A$4:$J$9, 9, FALSE)+Constants!$B$50)) | S11: =R11/$R$6 | T11: =H11/(H11+M11) | U11: =M11/(H11+M11) | V11: =100/R11 | W11: =ROUNDUP(100/Q11, 0)
A12: 75 | B12: =(A12-1)*Constants!$B$90 | C12: Tier 3 (Rare) | D12: =10+ROUND(B12*0.5, 0) | E12: =100+(10+ROUND(B12*0.2, 0))*Constants!$B$35 | F12: =20*(1+D12/Constants!$B$30)*(Constants!$B$4/(Constants!$B$4+10)) | G12: =F12/(1-(10+ROUND(B12*0.1, 0))/(10+ROUND(B12*0.1, 0)+Constants!$B$50)) | H12: =G12/$G$6 | I12: =VLOOKUP(C12, GearTiers!$A$4:$J$9, 3, FALSE) | J12: =10+VLOOKUP(C12, GearTiers!$A$4:$J$9, 5, FALSE) | K12: =100+(10+VLOOKUP(C12, GearTiers!$A$4:$J$9, 7, FALSE))*Constants!$B$35 | L12: =(I12*(1+J12/Constants!$B$30)*(Constants!$B$4/(Constants!$B$4+10)))/(1-(10+VLOOKUP(C12, GearTiers!$A$4:$J$9, 9, FALSE))/(10+VLOOKUP(C12, GearTiers!$A$4:$J$9, 9, FALSE)+Constants!$B$50)) | M12: =L12/$L$6 | N12: =D12+VLOOKUP(C12, GearTiers!$A$4:$J$9, 5, FALSE) | O12: =E12+VLOOKUP(C12, GearTiers!$A$4:$J$9, 7, FALSE)*Constants!$B$35 | P12: =10+ROUND(B12*0.1, 0)+VLOOKUP(C12, GearTiers!$A$4:$K$9, 8, FALSE) | Q12: =I12*(1+N12/Constants!$B$30)*(Constants!$B$4/(Constants!$B$4+10)) | R12: =Q12/(1-(10+ROUND(B12*0.1, 0)+VLOOKUP(C12, GearTiers!$A$4:$J$9, 9, FALSE))/(10+ROUND(B12*0.1, 0)+VLOOKUP(C12, GearTiers!$A$4:$J$9, 9, FALSE)+Constants!$B$50)) | S12: =R12/$R$6 | T12: =H12/(H12+M12) | U12: =M12/(H12+M12) | V12: =100/R12 | W12: =ROUNDUP(100/Q12, 0)
A13: 100 | B13: =(A13-1)*Constants!$B$90 | C13: Tier 4 (Epic) | D13: =10+ROUND(B13*0.5, 0) | E13: =100+(10+ROUND(B13*0.2, 0))*Constants!$B$35 | F13: =20*(1+D13/Constants!$B$30)*(Constants!$B$4/(Constants!$B$4+10)) | G13: =F13/(1-(10+ROUND(B13*0.1, 0))/(10+ROUND(B13*0.1, 0)+Constants!$B$50)) | H13: =G13/$G$6 | I13: =VLOOKUP(C13, GearTiers!$A$4:$J$9, 3, FALSE) | J13: =10+VLOOKUP(C13, GearTiers!$A$4:$J$9, 5, FALSE) | K13: =100+(10+VLOOKUP(C13, GearTiers!$A$4:$J$9, 7, FALSE))*Constants!$B$35 | L13: =(I13*(1+J13/Constants!$B$30)*(Constants!$B$4/(Constants!$B$4+10)))/(1-(10+VLOOKUP(C13, GearTiers!$A$4:$J$9, 9, FALSE))/(10+VLOOKUP(C13, GearTiers!$A$4:$J$9, 9, FALSE)+Constants!$B$50)) | M13: =L13/$L$6 | N13: =D13+VLOOKUP(C13, GearTiers!$A$4:$J$9, 5, FALSE) | O13: =E13+VLOOKUP(C13, GearTiers!$A$4:$J$9, 7, FALSE)*Constants!$B$35 | P13: =10+ROUND(B13*0.1, 0)+VLOOKUP(C13, GearTiers!$A$4:$K$9, 8, FALSE) | Q13: =I13*(1+N13/Constants!$B$30)*(Constants!$B$4/(Constants!$B$4+10)) | R13: =Q13/(1-(10+ROUND(B13*0.1, 0)+VLOOKUP(C13, GearTiers!$A$4:$J$9, 9, FALSE))/(10+ROUND(B13*0.1, 0)+VLOOKUP(C13, GearTiers!$A$4:$J$9, 9, FALSE)+Constants!$B$50)) | S13: =R13/$R$6 | T13: =H13/(H13+M13) | U13: =M13/(H13+M13) | V13: =100/R13 | W13: =ROUNDUP(100/Q13, 0)
A14: 150 | B14: =(A14-1)*Constants!$B$90 | C14: Tier 4 (Epic) | D14: =10+ROUND(B14*0.5, 0) | E14: =100+(10+ROUND(B14*0.2, 0))*Constants!$B$35 | F14: =20*(1+D14/Constants!$B$30)*(Constants!$B$4/(Constants!$B$4+10)) | G14: =F14/(1-(10+ROUND(B14*0.1, 0))/(10+ROUND(B14*0.1, 0)+Constants!$B$50)) | H14: =G14/$G$6 | I14: =VLOOKUP(C14, GearTiers!$A$4:$J$9, 3, FALSE) | J14: =10+VLOOKUP(C14, GearTiers!$A$4:$J$9, 5, FALSE) | K14: =100+(10+VLOOKUP(C14, GearTiers!$A$4:$J$9, 7, FALSE))*Constants!$B$35 | L14: =(I14*(1+J14/Constants!$B$30)*(Constants!$B$4/(Constants!$B$4+10)))/(1-(10+VLOOKUP(C14, GearTiers!$A$4:$J$9, 9, FALSE))/(10+VLOOKUP(C14, GearTiers!$A$4:$J$9, 9, FALSE)+Constants!$B$50)) | M14: =L14/$L$6 | N14: =D14+VLOOKUP(C14, GearTiers!$A$4:$J$9, 5, FALSE) | O14: =E14+VLOOKUP(C14, GearTiers!$A$4:$J$9, 7, FALSE)*Constants!$B$35 | P14: =10+ROUND(B14*0.1, 0)+VLOOKUP(C14, GearTiers!$A$4:$K$9, 8, FALSE) | Q14: =I14*(1+N14/Constants!$B$30)*(Constants!$B$4/(Constants!$B$4+10)) | R14: =Q14/(1-(10+ROUND(B14*0.1, 0)+VLOOKUP(C14, GearTiers!$A$4:$J$9, 9, FALSE))/(10+ROUND(B14*0.1, 0)+VLOOKUP(C14, GearTiers!$A$4:$J$9, 9, FALSE)+Constants!$B$50)) | S14: =R14/$R$6 | T14: =H14/(H14+M14) | U14: =M14/(H14+M14) | V14: =100/R14 | W14: =ROUNDUP(100/Q14, 0)
A15: 200 | B15: =(A15-1)*Constants!$B$90 | C15: Tier 5 (Legendary) | D15: =10+ROUND(B15*0.5, 0) | E15: =100+(10+ROUND(B15*0.2, 0))*Constants!$B$35 | F15: =20*(1+D15/Constants!$B$30)*(Constants!$B$4/(Constants!$B$4+10)) | G15: =F15/(1-(10+ROUND(B15*0.1, 0))/(10+ROUND(B15*0.1, 0)+Constants!$B$50)) | H15: =G15/$G$6 | I15: =VLOOKUP(C15, GearTiers!$A$4:$J$9, 3, FALSE) | J15: =10+VLOOKUP(C15, GearTiers!$A$4:$J$9, 5, FALSE) | K15: =100+(10+VLOOKUP(C15, GearTiers!$A$4:$J$9, 7, FALSE))*Constants!$B$35 | L15: =(I15*(1+J15/Constants!$B$30)*(Constants!$B$4/(Constants!$B$4+10)))/(1-(10+VLOOKUP(C15, GearTiers!$A$4:$J$9, 9, FALSE))/(10+VLOOKUP(C15, GearTiers!$A$4:$J$9, 9, FALSE)+Constants!$B$50)) | M15: =L15/$L$6 | N15: =D15+VLOOKUP(C15, GearTiers!$A$4:$J$9, 5, FALSE) | O15: =E15+VLOOKUP(C15, GearTiers!$A$4:$J$9, 7, FALSE)*Constants!$B$35 | P15: =10+ROUND(B15*0.1, 0)+VLOOKUP(C15, GearTiers!$A$4:$K$9, 8, FALSE) | Q15: =I15*(1+N15/Constants!$B$30)*(Constants!$B$4/(Constants!$B$4+10)) | R15: =Q15/(1-(10+ROUND(B15*0.1, 0)+VLOOKUP(C15, GearTiers!$A$4:$J$9, 9, FALSE))/(10+ROUND(B15*0.1, 0)+VLOOKUP(C15, GearTiers!$A$4:$J$9, 9, FALSE)+Constants!$B$50)) | S15: =R15/$R$6 | T15: =H15/(H15+M15) | U15: =M15/(H15+M15) | V15: =100/R15 | W15: =ROUNDUP(100/Q15, 0)
